[2025-04-07T00:21:06.875+0000] {local_task_job_runner.py:120} INFO - ::group::Pre task execution logs
[2025-04-07T00:21:06.972+0000] {taskinstance.py:2073} INFO - Dependencies all met for dep_context=non-requeueable deps ti=<TaskInstance: tmdb_pipeline_optimized.generate_visualizations scheduled__2025-04-06T12:00:00+00:00 [queued]>
[2025-04-07T00:21:07.005+0000] {taskinstance.py:2073} INFO - Dependencies all met for dep_context=requeueable deps ti=<TaskInstance: tmdb_pipeline_optimized.generate_visualizations scheduled__2025-04-06T12:00:00+00:00 [queued]>
[2025-04-07T00:21:07.007+0000] {taskinstance.py:2303} INFO - Starting attempt 1 of 2
[2025-04-07T00:21:07.055+0000] {taskinstance.py:2327} INFO - Executing <Task(PythonOperator): generate_visualizations> on 2025-04-06 12:00:00+00:00
[2025-04-07T00:21:07.083+0000] {warnings.py:110} WARNING - /home/***/.local/lib/python3.12/site-packages/***/task/task_runner/standard_task_runner.py:61: DeprecationWarning: This process (pid=1372) is multi-threaded, use of fork() may lead to deadlocks in the child.
  pid = os.fork()

[2025-04-07T00:21:07.089+0000] {standard_task_runner.py:63} INFO - Started process 1396 to run task
[2025-04-07T00:21:07.091+0000] {standard_task_runner.py:90} INFO - Running: ['***', 'tasks', 'run', 'tmdb_pipeline_optimized', 'generate_visualizations', 'scheduled__2025-04-06T12:00:00+00:00', '--job-id', '339', '--raw', '--subdir', 'DAGS_FOLDER/tmdb_pipeline.py', '--cfg-path', '/tmp/tmplo1_ugj_']
[2025-04-07T00:21:07.101+0000] {standard_task_runner.py:91} INFO - Job 339: Subtask generate_visualizations
[2025-04-07T00:21:07.275+0000] {task_command.py:426} INFO - Running <TaskInstance: tmdb_pipeline_optimized.generate_visualizations scheduled__2025-04-06T12:00:00+00:00 [running]> on host 6daf0988e59d
[2025-04-07T00:21:07.604+0000] {taskinstance.py:2644} INFO - Exporting env vars: AIRFLOW_CTX_DAG_OWNER='gabriela' AIRFLOW_CTX_DAG_ID='tmdb_pipeline_optimized' AIRFLOW_CTX_TASK_ID='generate_visualizations' AIRFLOW_CTX_EXECUTION_DATE='2025-04-06T12:00:00+00:00' AIRFLOW_CTX_TRY_NUMBER='1' AIRFLOW_CTX_DAG_RUN_ID='scheduled__2025-04-06T12:00:00+00:00'
[2025-04-07T00:21:07.609+0000] {taskinstance.py:430} INFO - ::endgroup::
[2025-04-07T00:21:10.081+0000] {tmdb_pipeline.py:2299} ERROR - Error al generar visualizaciones: connection to server at "movie_postgres" (172.19.0.3), port 5433 failed: Connection refused
	Is the server running on that host and accepting TCP/IP connections?

[2025-04-07T00:21:10.089+0000] {tmdb_pipeline.py:2300} ERROR - Traceback (most recent call last):
  File "/opt/***/dags/tmdb_pipeline.py", line 2183, in generate_visualizations
    conn = psycopg2.connect(
           ^^^^^^^^^^^^^^^^^
  File "/home/***/.local/lib/python3.12/site-packages/psycopg2/__init__.py", line 122, in connect
    conn = _connect(dsn, connection_factory=connection_factory, **kwasync)
           ^^^^^^^^^^^^^^^^^^^^^^^^^^^^^^^^^^^^^^^^^^^^^^^^^^^^^^^^^^^^^^^
psycopg2.OperationalError: connection to server at "movie_postgres" (172.19.0.3), port 5433 failed: Connection refused
	Is the server running on that host and accepting TCP/IP connections?


[2025-04-07T00:21:10.091+0000] {taskinstance.py:441} INFO - ::group::Post task execution logs
[2025-04-07T00:21:10.093+0000] {taskinstance.py:2890} ERROR - Task failed with exception
Traceback (most recent call last):
  File "/home/airflow/.local/lib/python3.12/site-packages/airflow/models/taskinstance.py", line 465, in _execute_task
    result = _execute_callable(context=context, **execute_callable_kwargs)
             ^^^^^^^^^^^^^^^^^^^^^^^^^^^^^^^^^^^^^^^^^^^^^^^^^^^^^^^^^^^^^
  File "/home/airflow/.local/lib/python3.12/site-packages/airflow/models/taskinstance.py", line 432, in _execute_callable
    return execute_callable(context=context, **execute_callable_kwargs)
           ^^^^^^^^^^^^^^^^^^^^^^^^^^^^^^^^^^^^^^^^^^^^^^^^^^^^^^^^^^^^
  File "/home/airflow/.local/lib/python3.12/site-packages/airflow/models/baseoperator.py", line 400, in wrapper
    return func(self, *args, **kwargs)
           ^^^^^^^^^^^^^^^^^^^^^^^^^^^
  File "/home/airflow/.local/lib/python3.12/site-packages/airflow/operators/python.py", line 235, in execute
    return_value = self.execute_callable()
                   ^^^^^^^^^^^^^^^^^^^^^^^
  File "/home/airflow/.local/lib/python3.12/site-packages/airflow/operators/python.py", line 252, in execute_callable
    return self.python_callable(*self.op_args, **self.op_kwargs)
           ^^^^^^^^^^^^^^^^^^^^^^^^^^^^^^^^^^^^^^^^^^^^^^^^^^^^^
  File "/opt/airflow/dags/tmdb_pipeline.py", line 2183, in generate_visualizations
    conn = psycopg2.connect(
           ^^^^^^^^^^^^^^^^^
  File "/home/airflow/.local/lib/python3.12/site-packages/psycopg2/__init__.py", line 122, in connect
    conn = _connect(dsn, connection_factory=connection_factory, **kwasync)
           ^^^^^^^^^^^^^^^^^^^^^^^^^^^^^^^^^^^^^^^^^^^^^^^^^^^^^^^^^^^^^^^
psycopg2.OperationalError: connection to server at "movie_postgres" (172.19.0.3), port 5433 failed: Connection refused
	Is the server running on that host and accepting TCP/IP connections?

[2025-04-07T00:21:10.126+0000] {taskinstance.py:1205} INFO - Marking task as UP_FOR_RETRY. dag_id=tmdb_pipeline_optimized, task_id=generate_visualizations, execution_date=20250406T120000, start_date=20250407T002106, end_date=20250407T002110
[2025-04-07T00:21:10.174+0000] {standard_task_runner.py:110} ERROR - Failed to execute job 339 for task generate_visualizations (connection to server at "movie_postgres" (172.19.0.3), port 5433 failed: Connection refused
	Is the server running on that host and accepting TCP/IP connections?
; 1396)
[2025-04-07T00:21:10.228+0000] {local_task_job_runner.py:240} INFO - Task exited with return code 1
[2025-04-07T00:21:10.336+0000] {taskinstance.py:3482} INFO - 0 downstream tasks scheduled from follow-on schedule check
[2025-04-07T00:21:10.341+0000] {local_task_job_runner.py:222} INFO - ::endgroup::
