[2025-04-06T19:39:48.963+0000] {local_task_job_runner.py:120} INFO - ::group::Pre task execution logs
[2025-04-06T19:39:48.985+0000] {taskinstance.py:2073} INFO - Dependencies all met for dep_context=non-requeueable deps ti=<TaskInstance: tmdb_pipeline_optimized.generate_visualizations manual__2025-04-06T19:38:46.634467+00:00 [queued]>
[2025-04-06T19:39:49.031+0000] {taskinstance.py:2073} INFO - Dependencies all met for dep_context=requeueable deps ti=<TaskInstance: tmdb_pipeline_optimized.generate_visualizations manual__2025-04-06T19:38:46.634467+00:00 [queued]>
[2025-04-06T19:39:49.032+0000] {taskinstance.py:2303} INFO - Starting attempt 1 of 2
[2025-04-06T19:39:49.044+0000] {taskinstance.py:2327} INFO - Executing <Task(PythonOperator): generate_visualizations> on 2025-04-06 19:38:46.634467+00:00
[2025-04-06T19:39:49.053+0000] {warnings.py:110} WARNING - /home/***/.local/lib/python3.12/site-packages/***/task/task_runner/standard_task_runner.py:61: DeprecationWarning: This process (pid=378) is multi-threaded, use of fork() may lead to deadlocks in the child.
  pid = os.fork()

[2025-04-06T19:39:49.054+0000] {standard_task_runner.py:63} INFO - Started process 395 to run task
[2025-04-06T19:39:49.055+0000] {standard_task_runner.py:90} INFO - Running: ['***', 'tasks', 'run', 'tmdb_pipeline_optimized', 'generate_visualizations', 'manual__2025-04-06T19:38:46.634467+00:00', '--job-id', '332', '--raw', '--subdir', 'DAGS_FOLDER/tmdb_pipeline.py', '--cfg-path', '/tmp/tmp424k1y03']
[2025-04-06T19:39:49.057+0000] {standard_task_runner.py:91} INFO - Job 332: Subtask generate_visualizations
[2025-04-06T19:39:49.105+0000] {task_command.py:426} INFO - Running <TaskInstance: tmdb_pipeline_optimized.generate_visualizations manual__2025-04-06T19:38:46.634467+00:00 [running]> on host 6daf0988e59d
[2025-04-06T19:39:49.183+0000] {taskinstance.py:2644} INFO - Exporting env vars: AIRFLOW_CTX_DAG_OWNER='gabriela' AIRFLOW_CTX_DAG_ID='tmdb_pipeline_optimized' AIRFLOW_CTX_TASK_ID='generate_visualizations' AIRFLOW_CTX_EXECUTION_DATE='2025-04-06T19:38:46.634467+00:00' AIRFLOW_CTX_TRY_NUMBER='1' AIRFLOW_CTX_DAG_RUN_ID='manual__2025-04-06T19:38:46.634467+00:00'
[2025-04-06T19:39:49.184+0000] {taskinstance.py:430} INFO - ::endgroup::
[2025-04-06T19:39:49.868+0000] {font_manager.py:1639} INFO - generated new fontManager
[2025-04-06T19:39:50.191+0000] {tmdb_pipeline.py:2299} ERROR - Error al generar visualizaciones: connection to server at "movie_postgres" (172.19.0.3), port 5433 failed: Connection refused
	Is the server running on that host and accepting TCP/IP connections?

[2025-04-06T19:39:50.193+0000] {tmdb_pipeline.py:2300} ERROR - Traceback (most recent call last):
  File "/opt/***/dags/tmdb_pipeline.py", line 2183, in generate_visualizations
    conn = psycopg2.connect(
           ^^^^^^^^^^^^^^^^^
  File "/home/***/.local/lib/python3.12/site-packages/psycopg2/__init__.py", line 122, in connect
    conn = _connect(dsn, connection_factory=connection_factory, **kwasync)
           ^^^^^^^^^^^^^^^^^^^^^^^^^^^^^^^^^^^^^^^^^^^^^^^^^^^^^^^^^^^^^^^
psycopg2.OperationalError: connection to server at "movie_postgres" (172.19.0.3), port 5433 failed: Connection refused
	Is the server running on that host and accepting TCP/IP connections?


[2025-04-06T19:39:50.193+0000] {taskinstance.py:441} INFO - ::group::Post task execution logs
[2025-04-06T19:39:50.194+0000] {taskinstance.py:2890} ERROR - Task failed with exception
Traceback (most recent call last):
  File "/home/airflow/.local/lib/python3.12/site-packages/airflow/models/taskinstance.py", line 465, in _execute_task
    result = _execute_callable(context=context, **execute_callable_kwargs)
             ^^^^^^^^^^^^^^^^^^^^^^^^^^^^^^^^^^^^^^^^^^^^^^^^^^^^^^^^^^^^^
  File "/home/airflow/.local/lib/python3.12/site-packages/airflow/models/taskinstance.py", line 432, in _execute_callable
    return execute_callable(context=context, **execute_callable_kwargs)
           ^^^^^^^^^^^^^^^^^^^^^^^^^^^^^^^^^^^^^^^^^^^^^^^^^^^^^^^^^^^^
  File "/home/airflow/.local/lib/python3.12/site-packages/airflow/models/baseoperator.py", line 400, in wrapper
    return func(self, *args, **kwargs)
           ^^^^^^^^^^^^^^^^^^^^^^^^^^^
  File "/home/airflow/.local/lib/python3.12/site-packages/airflow/operators/python.py", line 235, in execute
    return_value = self.execute_callable()
                   ^^^^^^^^^^^^^^^^^^^^^^^
  File "/home/airflow/.local/lib/python3.12/site-packages/airflow/operators/python.py", line 252, in execute_callable
    return self.python_callable(*self.op_args, **self.op_kwargs)
           ^^^^^^^^^^^^^^^^^^^^^^^^^^^^^^^^^^^^^^^^^^^^^^^^^^^^^
  File "/opt/airflow/dags/tmdb_pipeline.py", line 2183, in generate_visualizations
    conn = psycopg2.connect(
           ^^^^^^^^^^^^^^^^^
  File "/home/airflow/.local/lib/python3.12/site-packages/psycopg2/__init__.py", line 122, in connect
    conn = _connect(dsn, connection_factory=connection_factory, **kwasync)
           ^^^^^^^^^^^^^^^^^^^^^^^^^^^^^^^^^^^^^^^^^^^^^^^^^^^^^^^^^^^^^^^
psycopg2.OperationalError: connection to server at "movie_postgres" (172.19.0.3), port 5433 failed: Connection refused
	Is the server running on that host and accepting TCP/IP connections?

[2025-04-06T19:39:50.204+0000] {taskinstance.py:1205} INFO - Marking task as UP_FOR_RETRY. dag_id=tmdb_pipeline_optimized, task_id=generate_visualizations, execution_date=20250406T193846, start_date=20250406T193949, end_date=20250406T193950
[2025-04-06T19:39:50.221+0000] {standard_task_runner.py:110} ERROR - Failed to execute job 332 for task generate_visualizations (connection to server at "movie_postgres" (172.19.0.3), port 5433 failed: Connection refused
	Is the server running on that host and accepting TCP/IP connections?
; 395)
[2025-04-06T19:39:50.264+0000] {local_task_job_runner.py:240} INFO - Task exited with return code 1
[2025-04-06T19:39:50.298+0000] {taskinstance.py:3482} INFO - 0 downstream tasks scheduled from follow-on schedule check
[2025-04-06T19:39:50.300+0000] {local_task_job_runner.py:222} INFO - ::endgroup::
