[2025-04-01T00:00:23.807+0000] {local_task_job_runner.py:120} INFO - ::group::Pre task execution logs
[2025-04-01T00:00:23.829+0000] {taskinstance.py:2073} INFO - Dependencies all met for dep_context=non-requeueable deps ti=<TaskInstance: tmdb_pipeline.process_kafka_data scheduled__2025-03-31T12:00:00+00:00 [queued]>
[2025-04-01T00:00:23.836+0000] {taskinstance.py:2073} INFO - Dependencies all met for dep_context=requeueable deps ti=<TaskInstance: tmdb_pipeline.process_kafka_data scheduled__2025-03-31T12:00:00+00:00 [queued]>
[2025-04-01T00:00:23.837+0000] {taskinstance.py:2303} INFO - Starting attempt 1 of 3
[2025-04-01T00:00:23.850+0000] {taskinstance.py:2327} INFO - Executing <Task(PythonOperator): process_kafka_data> on 2025-03-31 12:00:00+00:00
[2025-04-01T00:00:23.857+0000] {warnings.py:110} WARNING - /home/***/.local/lib/python3.12/site-packages/***/task/task_runner/standard_task_runner.py:61: DeprecationWarning: This process (pid=1281) is multi-threaded, use of fork() may lead to deadlocks in the child.
  pid = os.fork()

[2025-04-01T00:00:23.858+0000] {standard_task_runner.py:63} INFO - Started process 1283 to run task
[2025-04-01T00:00:23.859+0000] {standard_task_runner.py:90} INFO - Running: ['***', 'tasks', 'run', 'tmdb_pipeline', 'process_kafka_data', 'scheduled__2025-03-31T12:00:00+00:00', '--job-id', '34', '--raw', '--subdir', 'DAGS_FOLDER/tmdb_pipeline.py', '--cfg-path', '/tmp/tmp7q_2brju']
[2025-04-01T00:00:23.861+0000] {standard_task_runner.py:91} INFO - Job 34: Subtask process_kafka_data
[2025-04-01T00:00:23.906+0000] {task_command.py:426} INFO - Running <TaskInstance: tmdb_pipeline.process_kafka_data scheduled__2025-03-31T12:00:00+00:00 [running]> on host 488700525f48
[2025-04-01T00:00:23.984+0000] {taskinstance.py:2644} INFO - Exporting env vars: AIRFLOW_CTX_DAG_OWNER='gabriela' AIRFLOW_CTX_DAG_ID='tmdb_pipeline' AIRFLOW_CTX_TASK_ID='process_kafka_data' AIRFLOW_CTX_EXECUTION_DATE='2025-03-31T12:00:00+00:00' AIRFLOW_CTX_TRY_NUMBER='1' AIRFLOW_CTX_DAG_RUN_ID='scheduled__2025-03-31T12:00:00+00:00'
[2025-04-01T00:00:23.985+0000] {taskinstance.py:430} INFO - ::endgroup::
[2025-04-01T00:00:26.060+0000] {proxy.py:85} INFO - To route to workers diagnostics web server please install jupyter-server-proxy: python -m pip install jupyter-server-proxy
[2025-04-01T00:00:26.064+0000] {warnings.py:110} WARNING - /home/***/.local/lib/python3.12/site-packages/distributed/node.py:187: UserWarning: Port 8787 is already in use.
Perhaps you already have a cluster running?
Hosting the HTTP server on port 34571 instead
  warnings.warn(

[2025-04-01T00:00:26.094+0000] {scheduler.py:1754} INFO - State start
[2025-04-01T00:00:26.102+0000] {scheduler.py:4209} INFO -   Scheduler at:     tcp://127.0.0.1:42055
[2025-04-01T00:00:26.102+0000] {scheduler.py:4224} INFO -   dashboard at:  http://127.0.0.1:34571/status
[2025-04-01T00:00:26.103+0000] {scheduler.py:8127} INFO - Registering Worker plugin shuffle
[2025-04-01T00:00:26.116+0000] {nanny.py:368} INFO -         Start Nanny at: 'tcp://127.0.0.1:36067'
[2025-04-01T00:00:26.125+0000] {nanny.py:368} INFO -         Start Nanny at: 'tcp://127.0.0.1:43895'
[2025-04-01T00:00:26.128+0000] {nanny.py:454} ERROR - Failed to start process
Traceback (most recent call last):
  File "/home/airflow/.local/lib/python3.12/site-packages/distributed/nanny.py", line 452, in instantiate
    result = await self.process.start()
             ^^^^^^^^^^^^^^^^^^^^^^^^^^
  File "/home/airflow/.local/lib/python3.12/site-packages/distributed/nanny.py", line 750, in start
    await self.process.start()
  File "/home/airflow/.local/lib/python3.12/site-packages/distributed/process.py", line 55, in _call_and_set_future
    res = func(*args, **kwargs)
          ^^^^^^^^^^^^^^^^^^^^^
  File "/home/airflow/.local/lib/python3.12/site-packages/distributed/process.py", line 215, in _start
    process.start()
  File "/usr/local/lib/python3.12/multiprocessing/process.py", line 118, in start
    assert not _current_process._config.get('daemon'), \
AssertionError: daemonic processes are not allowed to have children
[2025-04-01T00:00:26.130+0000] {nanny.py:611} INFO - Closing Nanny at 'tcp://127.0.0.1:36067'. Reason: nanny-instantiate-failed
[2025-04-01T00:00:26.131+0000] {nanny.py:454} ERROR - Failed to start process
Traceback (most recent call last):
  File "/home/airflow/.local/lib/python3.12/site-packages/distributed/nanny.py", line 452, in instantiate
    result = await self.process.start()
             ^^^^^^^^^^^^^^^^^^^^^^^^^^
  File "/home/airflow/.local/lib/python3.12/site-packages/distributed/nanny.py", line 750, in start
    await self.process.start()
  File "/home/airflow/.local/lib/python3.12/site-packages/distributed/process.py", line 55, in _call_and_set_future
    res = func(*args, **kwargs)
          ^^^^^^^^^^^^^^^^^^^^^
  File "/home/airflow/.local/lib/python3.12/site-packages/distributed/process.py", line 215, in _start
    process.start()
  File "/usr/local/lib/python3.12/multiprocessing/process.py", line 118, in start
    assert not _current_process._config.get('daemon'), \
AssertionError: daemonic processes are not allowed to have children
[2025-04-01T00:00:26.132+0000] {nanny.py:611} INFO - Closing Nanny at 'tcp://127.0.0.1:43895'. Reason: nanny-instantiate-failed
[2025-04-01T02:45:03.961+0000] {core.py:608} INFO - Event loop was unresponsive in Scheduler for 269.95s.  This is often caused by long-running GIL-holding functions or moving large chunks of data. This can cause timeouts and instability.
[2025-04-01T02:45:04.764+0000] {core.py:608} INFO - Event loop was unresponsive in Scheduler for 3.28s.  This is often caused by long-running GIL-holding functions or moving large chunks of data. This can cause timeouts and instability.
[2025-04-01T04:31:39.361+0000] {core.py:608} INFO - Event loop was unresponsive in Scheduler for 5.55s.  This is often caused by long-running GIL-holding functions or moving large chunks of data. This can cause timeouts and instability.
[2025-04-01T05:01:28.805+0000] {core.py:608} INFO - Event loop was unresponsive in Scheduler for 1709.21s.  This is often caused by long-running GIL-holding functions or moving large chunks of data. This can cause timeouts and instability.
[2025-04-01T05:31:32.684+0000] {core.py:608} INFO - Event loop was unresponsive in Scheduler for 1772.13s.  This is often caused by long-running GIL-holding functions or moving large chunks of data. This can cause timeouts and instability.
[2025-04-01T06:01:46.548+0000] {core.py:608} INFO - Event loop was unresponsive in Scheduler for 297.26s.  This is often caused by long-running GIL-holding functions or moving large chunks of data. This can cause timeouts and instability.
[2025-04-01T06:02:03.976+0000] {core.py:608} INFO - Event loop was unresponsive in Scheduler for 3.18s.  This is often caused by long-running GIL-holding functions or moving large chunks of data. This can cause timeouts and instability.
[2025-04-01T06:07:44.871+0000] {core.py:608} INFO - Event loop was unresponsive in Scheduler for 340.95s.  This is often caused by long-running GIL-holding functions or moving large chunks of data. This can cause timeouts and instability.
[2025-04-01T18:37:43.418+0000] {local_task_job_runner.py:120} INFO - ::group::Pre task execution logs
[2025-04-01T18:37:43.438+0000] {taskinstance.py:2063} INFO - Dependencies not met for <TaskInstance: tmdb_pipeline.process_kafka_data scheduled__2025-03-31T12:00:00+00:00 [running]>, dependency 'Task Instance State' FAILED: Task is in the 'running' state.
[2025-04-01T18:37:43.445+0000] {taskinstance.py:2063} INFO - Dependencies not met for <TaskInstance: tmdb_pipeline.process_kafka_data scheduled__2025-03-31T12:00:00+00:00 [running]>, dependency 'Task Instance Not Running' FAILED: Task is in the running state
[2025-04-01T18:37:43.446+0000] {local_task_job_runner.py:163} INFO - Task is not able to be run
