[2025-04-07T01:34:59.646+0000] {local_task_job_runner.py:120} INFO - ::group::Pre task execution logs
[2025-04-07T01:34:59.667+0000] {taskinstance.py:2073} INFO - Dependencies all met for dep_context=non-requeueable deps ti=<TaskInstance: tmdb_pipeline_optimized.train_ml_model manual__2025-04-07T01:31:41.064977+00:00 [queued]>
[2025-04-07T01:34:59.680+0000] {taskinstance.py:2073} INFO - Dependencies all met for dep_context=requeueable deps ti=<TaskInstance: tmdb_pipeline_optimized.train_ml_model manual__2025-04-07T01:31:41.064977+00:00 [queued]>
[2025-04-07T01:34:59.681+0000] {taskinstance.py:2303} INFO - Starting attempt 2 of 2
[2025-04-07T01:34:59.694+0000] {taskinstance.py:2327} INFO - Executing <Task(PythonOperator): train_ml_model> on 2025-04-07 01:31:41.064977+00:00
[2025-04-07T01:34:59.704+0000] {warnings.py:110} WARNING - /home/***/.local/lib/python3.12/site-packages/***/task/task_runner/standard_task_runner.py:61: DeprecationWarning: This process (pid=456) is multi-threaded, use of fork() may lead to deadlocks in the child.
  pid = os.fork()

[2025-04-07T01:34:59.706+0000] {standard_task_runner.py:63} INFO - Started process 473 to run task
[2025-04-07T01:34:59.706+0000] {standard_task_runner.py:90} INFO - Running: ['***', 'tasks', 'run', 'tmdb_pipeline_optimized', 'train_ml_model', 'manual__2025-04-07T01:31:41.064977+00:00', '--job-id', '349', '--raw', '--subdir', 'DAGS_FOLDER/tmdb_pipeline.py', '--cfg-path', '/tmp/tmphva6ixed']
[2025-04-07T01:34:59.710+0000] {standard_task_runner.py:91} INFO - Job 349: Subtask train_ml_model
[2025-04-07T01:34:59.782+0000] {task_command.py:426} INFO - Running <TaskInstance: tmdb_pipeline_optimized.train_ml_model manual__2025-04-07T01:31:41.064977+00:00 [running]> on host 6add7c178f3f
[2025-04-07T01:35:00.048+0000] {taskinstance.py:2644} INFO - Exporting env vars: AIRFLOW_CTX_DAG_OWNER='gabriela' AIRFLOW_CTX_DAG_ID='tmdb_pipeline_optimized' AIRFLOW_CTX_TASK_ID='train_ml_model' AIRFLOW_CTX_EXECUTION_DATE='2025-04-07T01:31:41.064977+00:00' AIRFLOW_CTX_TRY_NUMBER='2' AIRFLOW_CTX_DAG_RUN_ID='manual__2025-04-07T01:31:41.064977+00:00'
[2025-04-07T01:35:00.053+0000] {taskinstance.py:430} INFO - ::endgroup::
[2025-04-07T01:35:00.071+0000] {tmdb_pipeline.py:2743} ERROR - Error al entrenar modelo: connection to server at "movie_postgres" (172.19.0.4), port 5433 failed: Connection refused
	Is the server running on that host and accepting TCP/IP connections?

[2025-04-07T01:35:00.078+0000] {tmdb_pipeline.py:2744} ERROR - Traceback (most recent call last):
  File "/opt/***/dags/tmdb_pipeline.py", line 2577, in train_ml_model
    conn = psycopg2.connect(
           ^^^^^^^^^^^^^^^^^
  File "/home/***/.local/lib/python3.12/site-packages/psycopg2/__init__.py", line 122, in connect
    conn = _connect(dsn, connection_factory=connection_factory, **kwasync)
           ^^^^^^^^^^^^^^^^^^^^^^^^^^^^^^^^^^^^^^^^^^^^^^^^^^^^^^^^^^^^^^^
psycopg2.OperationalError: connection to server at "movie_postgres" (172.19.0.4), port 5433 failed: Connection refused
	Is the server running on that host and accepting TCP/IP connections?


[2025-04-07T01:35:00.079+0000] {taskinstance.py:441} INFO - ::group::Post task execution logs
[2025-04-07T01:35:00.079+0000] {taskinstance.py:2890} ERROR - Task failed with exception
Traceback (most recent call last):
  File "/home/airflow/.local/lib/python3.12/site-packages/airflow/models/taskinstance.py", line 465, in _execute_task
    result = _execute_callable(context=context, **execute_callable_kwargs)
             ^^^^^^^^^^^^^^^^^^^^^^^^^^^^^^^^^^^^^^^^^^^^^^^^^^^^^^^^^^^^^
  File "/home/airflow/.local/lib/python3.12/site-packages/airflow/models/taskinstance.py", line 432, in _execute_callable
    return execute_callable(context=context, **execute_callable_kwargs)
           ^^^^^^^^^^^^^^^^^^^^^^^^^^^^^^^^^^^^^^^^^^^^^^^^^^^^^^^^^^^^
  File "/home/airflow/.local/lib/python3.12/site-packages/airflow/models/baseoperator.py", line 400, in wrapper
    return func(self, *args, **kwargs)
           ^^^^^^^^^^^^^^^^^^^^^^^^^^^
  File "/home/airflow/.local/lib/python3.12/site-packages/airflow/operators/python.py", line 235, in execute
    return_value = self.execute_callable()
                   ^^^^^^^^^^^^^^^^^^^^^^^
  File "/home/airflow/.local/lib/python3.12/site-packages/airflow/operators/python.py", line 252, in execute_callable
    return self.python_callable(*self.op_args, **self.op_kwargs)
           ^^^^^^^^^^^^^^^^^^^^^^^^^^^^^^^^^^^^^^^^^^^^^^^^^^^^^
  File "/opt/airflow/dags/tmdb_pipeline.py", line 2577, in train_ml_model
    conn = psycopg2.connect(
           ^^^^^^^^^^^^^^^^^
  File "/home/airflow/.local/lib/python3.12/site-packages/psycopg2/__init__.py", line 122, in connect
    conn = _connect(dsn, connection_factory=connection_factory, **kwasync)
           ^^^^^^^^^^^^^^^^^^^^^^^^^^^^^^^^^^^^^^^^^^^^^^^^^^^^^^^^^^^^^^^
psycopg2.OperationalError: connection to server at "movie_postgres" (172.19.0.4), port 5433 failed: Connection refused
	Is the server running on that host and accepting TCP/IP connections?

[2025-04-07T01:35:00.103+0000] {taskinstance.py:1205} INFO - Marking task as FAILED. dag_id=tmdb_pipeline_optimized, task_id=train_ml_model, execution_date=20250407T013141, start_date=20250407T013459, end_date=20250407T013500
[2025-04-07T01:35:00.124+0000] {standard_task_runner.py:110} ERROR - Failed to execute job 349 for task train_ml_model (connection to server at "movie_postgres" (172.19.0.4), port 5433 failed: Connection refused
	Is the server running on that host and accepting TCP/IP connections?
; 473)
[2025-04-07T01:35:00.150+0000] {local_task_job_runner.py:240} INFO - Task exited with return code 1
[2025-04-07T01:35:00.263+0000] {taskinstance.py:3482} INFO - 0 downstream tasks scheduled from follow-on schedule check
[2025-04-07T01:35:00.270+0000] {local_task_job_runner.py:222} INFO - ::endgroup::
