[2025-04-12T13:04:32.961+0000] {local_task_job_runner.py:120} INFO - ::group::Pre task execution logs
[2025-04-12T13:04:32.980+0000] {taskinstance.py:2073} INFO - Dependencies all met for dep_context=non-requeueable deps ti=<TaskInstance: tmdb_pipeline_streamlit.fetch_and_send_to_kafka scheduled__2025-04-12T00:00:00+00:00 [queued]>
[2025-04-12T13:04:32.988+0000] {taskinstance.py:2073} INFO - Dependencies all met for dep_context=requeueable deps ti=<TaskInstance: tmdb_pipeline_streamlit.fetch_and_send_to_kafka scheduled__2025-04-12T00:00:00+00:00 [queued]>
[2025-04-12T13:04:32.988+0000] {taskinstance.py:2303} INFO - Starting attempt 1 of 2
[2025-04-12T13:04:33.001+0000] {taskinstance.py:2327} INFO - Executing <Task(PythonOperator): fetch_and_send_to_kafka> on 2025-04-12 00:00:00+00:00
[2025-04-12T13:04:33.014+0000] {standard_task_runner.py:63} INFO - Started process 10882 to run task
[2025-04-12T13:04:33.017+0000] {standard_task_runner.py:90} INFO - Running: ['***', 'tasks', 'run', 'tmdb_pipeline_streamlit', 'fetch_and_send_to_kafka', 'scheduled__2025-04-12T00:00:00+00:00', '--job-id', '1116', '--raw', '--subdir', 'DAGS_FOLDER/tmdb_pipeline.py', '--cfg-path', '/tmp/tmprgto__ma']
[2025-04-12T13:04:33.020+0000] {standard_task_runner.py:91} INFO - Job 1116: Subtask fetch_and_send_to_kafka
[2025-04-12T13:04:33.064+0000] {task_command.py:426} INFO - Running <TaskInstance: tmdb_pipeline_streamlit.fetch_and_send_to_kafka scheduled__2025-04-12T00:00:00+00:00 [running]> on host d6f276a13019
[2025-04-12T13:04:33.153+0000] {taskinstance.py:2644} INFO - Exporting env vars: AIRFLOW_CTX_DAG_OWNER='***' AIRFLOW_CTX_DAG_ID='tmdb_pipeline_streamlit' AIRFLOW_CTX_TASK_ID='fetch_and_send_to_kafka' AIRFLOW_CTX_EXECUTION_DATE='2025-04-12T00:00:00+00:00' AIRFLOW_CTX_TRY_NUMBER='1' AIRFLOW_CTX_DAG_RUN_ID='scheduled__2025-04-12T00:00:00+00:00'
[2025-04-12T13:04:33.155+0000] {taskinstance.py:430} INFO - ::endgroup::
[2025-04-12T13:04:33.260+0000] {conn.py:395} INFO - <BrokerConnection client_id=kafka-python-producer-1, node_id=bootstrap-0 host=kafka:9093 <connecting> [IPv4 ('172.19.0.6', 9093)]>: connecting to kafka:9093 [('172.19.0.6', 9093) IPv4]
[2025-04-12T13:04:33.263+0000] {conn.py:615} INFO - <BrokerConnection client_id=kafka-python-producer-1, node_id=bootstrap-0 host=kafka:9093 <checking_api_versions_recv> [IPv4 ('172.19.0.6', 9093)]>: Broker version identified as 2.6
[2025-04-12T13:04:33.264+0000] {conn.py:456} INFO - <BrokerConnection client_id=kafka-python-producer-1, node_id=bootstrap-0 host=kafka:9093 <connected> [IPv4 ('172.19.0.6', 9093)]>: Connection complete.
[2025-04-12T13:04:33.266+0000] {tmdb_pipeline.py:448} INFO - Productor Kafka conectado a kafka:9093
[2025-04-12T13:04:33.267+0000] {tmdb_pipeline.py:461} INFO - Obteniendo películas populares de TMDB
[2025-04-12T13:04:33.542+0000] {tmdb_pipeline.py:468} INFO - Obtenidas 20 películas populares (página 1)
[2025-04-12T13:04:33.833+0000] {tmdb_pipeline.py:468} INFO - Obtenidas 20 películas populares (página 2)
[2025-04-12T13:04:34.125+0000] {tmdb_pipeline.py:468} INFO - Obtenidas 20 películas populares (página 3)
[2025-04-12T13:04:34.424+0000] {tmdb_pipeline.py:468} INFO - Obtenidas 20 películas populares (página 4)
[2025-04-12T13:04:34.714+0000] {tmdb_pipeline.py:468} INFO - Obtenidas 20 películas populares (página 5)
[2025-04-12T13:04:34.714+0000] {tmdb_pipeline.py:477} INFO - Obteniendo películas mejor valoradas de TMDB
[2025-04-12T13:04:35.019+0000] {tmdb_pipeline.py:484} INFO - Obtenidas 20 películas mejor valoradas (página 1)
[2025-04-12T13:04:35.302+0000] {tmdb_pipeline.py:484} INFO - Obtenidas 20 películas mejor valoradas (página 2)
[2025-04-12T13:04:35.581+0000] {tmdb_pipeline.py:484} INFO - Obtenidas 20 películas mejor valoradas (página 3)
[2025-04-12T13:04:35.851+0000] {tmdb_pipeline.py:484} INFO - Obtenidas 20 películas mejor valoradas (página 4)
[2025-04-12T13:04:36.148+0000] {tmdb_pipeline.py:484} INFO - Obtenidas 20 películas mejor valoradas (página 5)
[2025-04-12T13:04:36.149+0000] {tmdb_pipeline.py:493} INFO - Obteniendo próximos estrenos de TMDB
[2025-04-12T13:39:17.353+0000] {tmdb_pipeline.py:619} ERROR - Error en la obtención de datos TMDB: ('Connection aborted.', RemoteDisconnected('Remote end closed connection without response'))
[2025-04-12T13:39:17.390+0000] {tmdb_pipeline.py:620} ERROR - Traceback (most recent call last):
  File "/home/***/.local/lib/python3.12/site-packages/urllib3/connectionpool.py", line 715, in urlopen
    httplib_response = self._make_request(
                       ^^^^^^^^^^^^^^^^^^^
  File "/home/***/.local/lib/python3.12/site-packages/urllib3/connectionpool.py", line 467, in _make_request
    six.raise_from(e, None)
  File "<string>", line 3, in raise_from
  File "/home/***/.local/lib/python3.12/site-packages/urllib3/connectionpool.py", line 462, in _make_request
    httplib_response = conn.getresponse()
                       ^^^^^^^^^^^^^^^^^^
  File "/usr/local/lib/python3.12/http/client.py", line 1423, in getresponse
    response.begin()
  File "/usr/local/lib/python3.12/http/client.py", line 331, in begin
    version, status, reason = self._read_status()
                              ^^^^^^^^^^^^^^^^^^^
  File "/usr/local/lib/python3.12/http/client.py", line 300, in _read_status
    raise RemoteDisconnected("Remote end closed connection without"
http.client.RemoteDisconnected: Remote end closed connection without response

During handling of the above exception, another exception occurred:

Traceback (most recent call last):
  File "/home/***/.local/lib/python3.12/site-packages/requests/adapters.py", line 486, in send
    resp = conn.urlopen(
           ^^^^^^^^^^^^^
  File "/home/***/.local/lib/python3.12/site-packages/urllib3/connectionpool.py", line 799, in urlopen
    retries = retries.increment(
              ^^^^^^^^^^^^^^^^^^
  File "/home/***/.local/lib/python3.12/site-packages/urllib3/util/retry.py", line 550, in increment
    raise six.reraise(type(error), error, _stacktrace)
          ^^^^^^^^^^^^^^^^^^^^^^^^^^^^^^^^^^^^^^^^^^^^
  File "/home/***/.local/lib/python3.12/site-packages/urllib3/packages/six.py", line 769, in reraise
    raise value.with_traceback(tb)
  File "/home/***/.local/lib/python3.12/site-packages/urllib3/connectionpool.py", line 715, in urlopen
    httplib_response = self._make_request(
                       ^^^^^^^^^^^^^^^^^^^
  File "/home/***/.local/lib/python3.12/site-packages/urllib3/connectionpool.py", line 467, in _make_request
    six.raise_from(e, None)
  File "<string>", line 3, in raise_from
  File "/home/***/.local/lib/python3.12/site-packages/urllib3/connectionpool.py", line 462, in _make_request
    httplib_response = conn.getresponse()
                       ^^^^^^^^^^^^^^^^^^
  File "/usr/local/lib/python3.12/http/client.py", line 1423, in getresponse
    response.begin()
  File "/usr/local/lib/python3.12/http/client.py", line 331, in begin
    version, status, reason = self._read_status()
                              ^^^^^^^^^^^^^^^^^^^
  File "/usr/local/lib/python3.12/http/client.py", line 300, in _read_status
    raise RemoteDisconnected("Remote end closed connection without"
urllib3.exceptions.ProtocolError: ('Connection aborted.', RemoteDisconnected('Remote end closed connection without response'))

During handling of the above exception, another exception occurred:

Traceback (most recent call last):
  File "/opt/***/dags/tmdb_pipeline.py", line 496, in fetch_and_send_to_kafka
    response = requests.get(url, headers=headers)
               ^^^^^^^^^^^^^^^^^^^^^^^^^^^^^^^^^^
  File "/home/***/.local/lib/python3.12/site-packages/requests/api.py", line 73, in get
    return request("get", url, params=params, **kwargs)
           ^^^^^^^^^^^^^^^^^^^^^^^^^^^^^^^^^^^^^^^^^^^^
  File "/home/***/.local/lib/python3.12/site-packages/requests/api.py", line 59, in request
    return session.request(method=method, url=url, **kwargs)
           ^^^^^^^^^^^^^^^^^^^^^^^^^^^^^^^^^^^^^^^^^^^^^^^^^
  File "/home/***/.local/lib/python3.12/site-packages/requests/sessions.py", line 589, in request
    resp = self.send(prep, **send_kwargs)
           ^^^^^^^^^^^^^^^^^^^^^^^^^^^^^^
  File "/home/***/.local/lib/python3.12/site-packages/requests/sessions.py", line 703, in send
    r = adapter.send(request, **kwargs)
        ^^^^^^^^^^^^^^^^^^^^^^^^^^^^^^^
  File "/home/***/.local/lib/python3.12/site-packages/requests/adapters.py", line 501, in send
    raise ConnectionError(err, request=request)
requests.exceptions.ConnectionError: ('Connection aborted.', RemoteDisconnected('Remote end closed connection without response'))

[2025-04-12T13:39:17.408+0000] {taskinstance.py:441} INFO - ::group::Post task execution logs
[2025-04-12T13:39:17.412+0000] {taskinstance.py:2890} ERROR - Task failed with exception
Traceback (most recent call last):
  File "/home/airflow/.local/lib/python3.12/site-packages/urllib3/connectionpool.py", line 715, in urlopen
    httplib_response = self._make_request(
                       ^^^^^^^^^^^^^^^^^^^
  File "/home/airflow/.local/lib/python3.12/site-packages/urllib3/connectionpool.py", line 467, in _make_request
    six.raise_from(e, None)
  File "<string>", line 3, in raise_from
  File "/home/airflow/.local/lib/python3.12/site-packages/urllib3/connectionpool.py", line 462, in _make_request
    httplib_response = conn.getresponse()
                       ^^^^^^^^^^^^^^^^^^
  File "/usr/local/lib/python3.12/http/client.py", line 1423, in getresponse
    response.begin()
  File "/usr/local/lib/python3.12/http/client.py", line 331, in begin
    version, status, reason = self._read_status()
                              ^^^^^^^^^^^^^^^^^^^
  File "/usr/local/lib/python3.12/http/client.py", line 300, in _read_status
    raise RemoteDisconnected("Remote end closed connection without"
http.client.RemoteDisconnected: Remote end closed connection without response

During handling of the above exception, another exception occurred:

Traceback (most recent call last):
  File "/home/airflow/.local/lib/python3.12/site-packages/requests/adapters.py", line 486, in send
    resp = conn.urlopen(
           ^^^^^^^^^^^^^
  File "/home/airflow/.local/lib/python3.12/site-packages/urllib3/connectionpool.py", line 799, in urlopen
    retries = retries.increment(
              ^^^^^^^^^^^^^^^^^^
  File "/home/airflow/.local/lib/python3.12/site-packages/urllib3/util/retry.py", line 550, in increment
    raise six.reraise(type(error), error, _stacktrace)
          ^^^^^^^^^^^^^^^^^^^^^^^^^^^^^^^^^^^^^^^^^^^^
  File "/home/airflow/.local/lib/python3.12/site-packages/urllib3/packages/six.py", line 769, in reraise
    raise value.with_traceback(tb)
  File "/home/airflow/.local/lib/python3.12/site-packages/urllib3/connectionpool.py", line 715, in urlopen
    httplib_response = self._make_request(
                       ^^^^^^^^^^^^^^^^^^^
  File "/home/airflow/.local/lib/python3.12/site-packages/urllib3/connectionpool.py", line 467, in _make_request
    six.raise_from(e, None)
  File "<string>", line 3, in raise_from
  File "/home/airflow/.local/lib/python3.12/site-packages/urllib3/connectionpool.py", line 462, in _make_request
    httplib_response = conn.getresponse()
                       ^^^^^^^^^^^^^^^^^^
  File "/usr/local/lib/python3.12/http/client.py", line 1423, in getresponse
    response.begin()
  File "/usr/local/lib/python3.12/http/client.py", line 331, in begin
    version, status, reason = self._read_status()
                              ^^^^^^^^^^^^^^^^^^^
  File "/usr/local/lib/python3.12/http/client.py", line 300, in _read_status
    raise RemoteDisconnected("Remote end closed connection without"
urllib3.exceptions.ProtocolError: ('Connection aborted.', RemoteDisconnected('Remote end closed connection without response'))

During handling of the above exception, another exception occurred:

Traceback (most recent call last):
  File "/home/airflow/.local/lib/python3.12/site-packages/airflow/models/taskinstance.py", line 465, in _execute_task
    result = _execute_callable(context=context, **execute_callable_kwargs)
             ^^^^^^^^^^^^^^^^^^^^^^^^^^^^^^^^^^^^^^^^^^^^^^^^^^^^^^^^^^^^^
  File "/home/airflow/.local/lib/python3.12/site-packages/airflow/models/taskinstance.py", line 432, in _execute_callable
    return execute_callable(context=context, **execute_callable_kwargs)
           ^^^^^^^^^^^^^^^^^^^^^^^^^^^^^^^^^^^^^^^^^^^^^^^^^^^^^^^^^^^^
  File "/home/airflow/.local/lib/python3.12/site-packages/airflow/models/baseoperator.py", line 400, in wrapper
    return func(self, *args, **kwargs)
           ^^^^^^^^^^^^^^^^^^^^^^^^^^^
  File "/home/airflow/.local/lib/python3.12/site-packages/airflow/operators/python.py", line 235, in execute
    return_value = self.execute_callable()
                   ^^^^^^^^^^^^^^^^^^^^^^^
  File "/home/airflow/.local/lib/python3.12/site-packages/airflow/operators/python.py", line 252, in execute_callable
    return self.python_callable(*self.op_args, **self.op_kwargs)
           ^^^^^^^^^^^^^^^^^^^^^^^^^^^^^^^^^^^^^^^^^^^^^^^^^^^^^
  File "/opt/airflow/dags/tmdb_pipeline.py", line 496, in fetch_and_send_to_kafka
    response = requests.get(url, headers=headers)
               ^^^^^^^^^^^^^^^^^^^^^^^^^^^^^^^^^^
  File "/home/airflow/.local/lib/python3.12/site-packages/requests/api.py", line 73, in get
    return request("get", url, params=params, **kwargs)
           ^^^^^^^^^^^^^^^^^^^^^^^^^^^^^^^^^^^^^^^^^^^^
  File "/home/airflow/.local/lib/python3.12/site-packages/requests/api.py", line 59, in request
    return session.request(method=method, url=url, **kwargs)
           ^^^^^^^^^^^^^^^^^^^^^^^^^^^^^^^^^^^^^^^^^^^^^^^^^
  File "/home/airflow/.local/lib/python3.12/site-packages/requests/sessions.py", line 589, in request
    resp = self.send(prep, **send_kwargs)
           ^^^^^^^^^^^^^^^^^^^^^^^^^^^^^^
  File "/home/airflow/.local/lib/python3.12/site-packages/requests/sessions.py", line 703, in send
    r = adapter.send(request, **kwargs)
        ^^^^^^^^^^^^^^^^^^^^^^^^^^^^^^^
  File "/home/airflow/.local/lib/python3.12/site-packages/requests/adapters.py", line 501, in send
    raise ConnectionError(err, request=request)
requests.exceptions.ConnectionError: ('Connection aborted.', RemoteDisconnected('Remote end closed connection without response'))
[2025-04-12T13:39:17.443+0000] {taskinstance.py:1205} INFO - Marking task as UP_FOR_RETRY. dag_id=tmdb_pipeline_streamlit, task_id=fetch_and_send_to_kafka, execution_date=20250412T000000, start_date=20250412T130432, end_date=20250412T133917
[2025-04-12T13:39:17.480+0000] {standard_task_runner.py:110} ERROR - Failed to execute job 1116 for task fetch_and_send_to_kafka (('Connection aborted.', RemoteDisconnected('Remote end closed connection without response')); 10882)
[2025-04-12T13:39:17.533+0000] {local_task_job_runner.py:240} INFO - Task exited with return code 1
[2025-04-12T13:39:17.589+0000] {taskinstance.py:3482} INFO - 0 downstream tasks scheduled from follow-on schedule check
[2025-04-12T13:39:17.592+0000] {local_task_job_runner.py:222} INFO - ::endgroup::
