[2025-04-07T02:36:27.363+0000] {local_task_job_runner.py:120} INFO - ::group::Pre task execution logs
[2025-04-07T02:36:27.383+0000] {taskinstance.py:2073} INFO - Dependencies all met for dep_context=non-requeueable deps ti=<TaskInstance: tmdb_pipeline_streamlit.generate_visualizations manual__2025-04-07T02:31:34.607687+00:00 [queued]>
[2025-04-07T02:36:27.390+0000] {taskinstance.py:2073} INFO - Dependencies all met for dep_context=requeueable deps ti=<TaskInstance: tmdb_pipeline_streamlit.generate_visualizations manual__2025-04-07T02:31:34.607687+00:00 [queued]>
[2025-04-07T02:36:27.391+0000] {taskinstance.py:2303} INFO - Starting attempt 3 of 3
[2025-04-07T02:36:27.403+0000] {taskinstance.py:2327} INFO - Executing <Task(PythonOperator): generate_visualizations> on 2025-04-07 02:31:34.607687+00:00
[2025-04-07T02:36:27.417+0000] {warnings.py:110} WARNING - /home/***/.local/lib/python3.12/site-packages/***/task/task_runner/standard_task_runner.py:61: DeprecationWarning: This process (pid=459) is multi-threaded, use of fork() may lead to deadlocks in the child.
  pid = os.fork()

[2025-04-07T02:36:27.419+0000] {standard_task_runner.py:63} INFO - Started process 476 to run task
[2025-04-07T02:36:27.419+0000] {standard_task_runner.py:90} INFO - Running: ['***', 'tasks', 'run', 'tmdb_pipeline_streamlit', 'generate_visualizations', 'manual__2025-04-07T02:31:34.607687+00:00', '--job-id', '395', '--raw', '--subdir', 'DAGS_FOLDER/tmdb_pipeline.py', '--cfg-path', '/tmp/tmp8abueao4']
[2025-04-07T02:36:27.421+0000] {standard_task_runner.py:91} INFO - Job 395: Subtask generate_visualizations
[2025-04-07T02:36:27.463+0000] {task_command.py:426} INFO - Running <TaskInstance: tmdb_pipeline_streamlit.generate_visualizations manual__2025-04-07T02:31:34.607687+00:00 [running]> on host 240e2c93ba02
[2025-04-07T02:36:27.554+0000] {taskinstance.py:2644} INFO - Exporting env vars: AIRFLOW_CTX_DAG_OWNER='gabriela' AIRFLOW_CTX_DAG_ID='tmdb_pipeline_streamlit' AIRFLOW_CTX_TASK_ID='generate_visualizations' AIRFLOW_CTX_EXECUTION_DATE='2025-04-07T02:31:34.607687+00:00' AIRFLOW_CTX_TRY_NUMBER='3' AIRFLOW_CTX_DAG_RUN_ID='manual__2025-04-07T02:31:34.607687+00:00'
[2025-04-07T02:36:27.556+0000] {taskinstance.py:430} INFO - ::endgroup::
[2025-04-07T02:36:27.570+0000] {tmdb_pipeline.py:1727} ERROR - Error al leer datos de PostgreSQL: connection to server at "movie_postgres" (172.19.0.3), port 5433 failed: Connection refused
	Is the server running on that host and accepting TCP/IP connections?

[2025-04-07T02:36:27.573+0000] {tmdb_pipeline.py:1728} ERROR - Traceback (most recent call last):
  File "/opt/***/dags/tmdb_pipeline.py", line 1695, in generate_visualizations
    conn = psycopg2.connect(
           ^^^^^^^^^^^^^^^^^
  File "/home/***/.local/lib/python3.12/site-packages/psycopg2/__init__.py", line 122, in connect
    conn = _connect(dsn, connection_factory=connection_factory, **kwasync)
           ^^^^^^^^^^^^^^^^^^^^^^^^^^^^^^^^^^^^^^^^^^^^^^^^^^^^^^^^^^^^^^^
psycopg2.OperationalError: connection to server at "movie_postgres" (172.19.0.3), port 5433 failed: Connection refused
	Is the server running on that host and accepting TCP/IP connections?


[2025-04-07T02:36:27.597+0000] {tmdb_pipeline.py:1809} ERROR - Error al generar visualizaciones: module 'datetime' has no attribute 'now'
[2025-04-07T02:36:27.598+0000] {tmdb_pipeline.py:1810} ERROR - Traceback (most recent call last):
  File "/opt/***/dags/tmdb_pipeline.py", line 1769, in generate_visualizations
    visualizations_dir = f"{OUTPUT_DIR}/visualizations_v3_{datetime.now().strftime('%Y%m%d_%H%M%S')}"
                                                           ^^^^^^^^^^^^
AttributeError: module 'datetime' has no attribute 'now'

[2025-04-07T02:36:27.599+0000] {taskinstance.py:441} INFO - ::group::Post task execution logs
[2025-04-07T02:36:27.599+0000] {taskinstance.py:2890} ERROR - Task failed with exception
Traceback (most recent call last):
  File "/home/airflow/.local/lib/python3.12/site-packages/airflow/models/taskinstance.py", line 465, in _execute_task
    result = _execute_callable(context=context, **execute_callable_kwargs)
             ^^^^^^^^^^^^^^^^^^^^^^^^^^^^^^^^^^^^^^^^^^^^^^^^^^^^^^^^^^^^^
  File "/home/airflow/.local/lib/python3.12/site-packages/airflow/models/taskinstance.py", line 432, in _execute_callable
    return execute_callable(context=context, **execute_callable_kwargs)
           ^^^^^^^^^^^^^^^^^^^^^^^^^^^^^^^^^^^^^^^^^^^^^^^^^^^^^^^^^^^^
  File "/home/airflow/.local/lib/python3.12/site-packages/airflow/models/baseoperator.py", line 400, in wrapper
    return func(self, *args, **kwargs)
           ^^^^^^^^^^^^^^^^^^^^^^^^^^^
  File "/home/airflow/.local/lib/python3.12/site-packages/airflow/operators/python.py", line 235, in execute
    return_value = self.execute_callable()
                   ^^^^^^^^^^^^^^^^^^^^^^^
  File "/home/airflow/.local/lib/python3.12/site-packages/airflow/operators/python.py", line 252, in execute_callable
    return self.python_callable(*self.op_args, **self.op_kwargs)
           ^^^^^^^^^^^^^^^^^^^^^^^^^^^^^^^^^^^^^^^^^^^^^^^^^^^^^
  File "/opt/airflow/dags/tmdb_pipeline.py", line 1769, in generate_visualizations
    visualizations_dir = f"{OUTPUT_DIR}/visualizations_v3_{datetime.now().strftime('%Y%m%d_%H%M%S')}"
                                                           ^^^^^^^^^^^^
AttributeError: module 'datetime' has no attribute 'now'
[2025-04-07T02:36:27.608+0000] {taskinstance.py:1205} INFO - Marking task as FAILED. dag_id=tmdb_pipeline_streamlit, task_id=generate_visualizations, execution_date=20250407T023134, start_date=20250407T023627, end_date=20250407T023627
[2025-04-07T02:36:27.620+0000] {standard_task_runner.py:110} ERROR - Failed to execute job 395 for task generate_visualizations (module 'datetime' has no attribute 'now'; 476)
[2025-04-07T02:36:27.645+0000] {local_task_job_runner.py:240} INFO - Task exited with return code 1
[2025-04-07T02:36:27.667+0000] {taskinstance.py:3482} INFO - 0 downstream tasks scheduled from follow-on schedule check
[2025-04-07T02:36:27.671+0000] {local_task_job_runner.py:222} INFO - ::endgroup::
